<?xml version="1.0" ?>
<!-- =================================================================================== -->
<!-- |    This document was autogenerated by xacro from fotis.urdf.xacro               | -->
<!-- |    EDITING THIS FILE BY HAND IS NOT RECOMMENDED                                 | -->
<!-- =================================================================================== -->
<robot name="arm" xmlns:xacro="http://www.ros.org/wiki/xacro">
  <!-- Joints Control in Gazebo -->
  <gazebo>
    <plugin filename="libgazebo_ros_control.so" name="gazebo_ros_control"/>
  </gazebo>
  <!-- Materials -->
  <material name="orange">
    <color rgba="1.00 0.67 0.02 1.00"/>
  </material>
  <material name="gray">
    <color rgba="0.80 0.80 0.80 1.00"/>
  </material>
  <!-- World frame (for Gazebo) -->
  <link name="world"/>
  <joint name="world_ball_joint" type="floating">
    <parent link="world"/>
    <child link="ball"/>
  </joint>
  <link name="ball">
    <visual>
      <geometry>
        <sphere radius="0.05"/>
        <origin rpy="0 0 0" xyz="0 0 0"/>
        <material name="green">
          <color rgba="0 1 0 1"/>
        </material>
      </geometry>
    </visual>
  </link>
  <transmission name="$ball_transmission">
    <type>transmission_interface/SimpleTransmission</type>
    <joint name="ball_joint">
      <hardwareInterface>hardware_interface/EffortJointInterface</hardwareInterface>
    </joint>
    <actuator name="ball_actuator"/>
  </transmission>
  <!-- Arm fixed to world frame  -->
  <joint name="world_foot_joint" type="fixed">
    <parent link="world"/>
    <child link="toe"/>
  </joint>
  <!-- Joints Chain -->
  <!--
  <xacro:arm_joint parent="toe" child="foot" axis="0 0 1" dist="${toe_length}"/>
  -->
  <joint name="toe_foot_joint" type="revolute">
    <origin rpy="0 0 -3.14159265359" xyz="0 0 0.03"/>
    <parent link="toe"/>
    <child link="foot"/>
    <axis xyz="0 0 -1"/>
    <limit effort="40.0" lower="-3.14159265359" upper="3.14159265359" velocity="1.0"/>
  </joint>
  <!-- Required for ROS control -->
  <transmission name="$toe_foot_transmission">
    <type>transmission_interface/SimpleTransmission</type>
    <joint name="toe_foot_joint">
      <hardwareInterface>hardware_interface/EffortJointInterface</hardwareInterface>
    </joint>
    <actuator name="toe_foot_actuator"/>
  </transmission>
  <link name="toe">
    <visual>
      <origin rpy="0 0 0" xyz="0 0 0.015"/>
      <geometry>
        <box size="0.02 0.02 0.03"/>
      </geometry>
      <material name="orange"/>
    </visual>
    <collision>
      <origin rpy="0 0 0" xyz="0 0 0.015"/>
      <geometry>
        <box size="0.02 0.02 0.03"/>
      </geometry>
    </collision>
    <inertial>
      <origin rpy="0 0 0" xyz="0 0 0.015"/>
      <mass value="1"/>
      <inertia ixx="0.00010833333333333333" ixy="0" ixz="0" iyy="0.00010833333333333333" iyz="0" izz="6.666666666666667e-05"/>
    </inertial>
    <visual>
      <origin rpy="0 0 0" xyz="0 0 0.03"/>
      <geometry>
        <cylinder length="0.025" radius="0.018"/>
      </geometry>
      <material name="gray"/>
    </visual>
    <collision>
      <origin rpy="0 0 0" xyz="0 0 0.03"/>
      <geometry>
        <cylinder length="0.025" radius="0.018"/>
      </geometry>
    </collision>
  </link>
  <!--
  <xacro:arm_joint parent="foot" child="leg" axis="1 0 0" dist="${foot_length}"/>
  -->
  <joint name="foot_leg_joint" type="revolute">
    <origin rpy="1.570796326795 0 0" xyz="0 0 0.04"/>
    <parent link="foot"/>
    <child link="leg"/>
    <axis xyz="-1 0 0"/>
    <limit effort="40.0" lower="-3.14159265359" upper="3.14159265359" velocity="1.0"/>
  </joint>
  <!-- Required for ROS control -->
  <transmission name="$foot_leg_transmission">
    <type>transmission_interface/SimpleTransmission</type>
    <joint name="foot_leg_joint">
      <hardwareInterface>hardware_interface/EffortJointInterface</hardwareInterface>
    </joint>
    <actuator name="foot_leg_actuator"/>
  </transmission>
  <link name="foot">
    <visual>
      <origin rpy="0 0 0" xyz="0 0 0.02"/>
      <geometry>
        <box size="0.02 0.02 0.04"/>
      </geometry>
      <material name="orange"/>
    </visual>
    <collision>
      <origin rpy="0 0 0" xyz="0 0 0.02"/>
      <geometry>
        <box size="0.02 0.02 0.04"/>
      </geometry>
    </collision>
    <inertial>
      <origin rpy="0 0 0" xyz="0 0 0.02"/>
      <mass value="1"/>
      <inertia ixx="0.00016666666666666666" ixy="0" ixz="0" iyy="0.00016666666666666666" iyz="0" izz="6.666666666666667e-05"/>
    </inertial>
    <visual>
      <origin rpy="0 1.570796326795 0" xyz="0 0 0.04"/>
      <geometry>
        <cylinder length="0.025" radius="0.018"/>
      </geometry>
      <material name="gray"/>
    </visual>
    <collision>
      <origin rpy="0 1.570796326795 0" xyz="0 0 0.04"/>
      <geometry>
        <cylinder length="0.025" radius="0.018"/>
      </geometry>
    </collision>
  </link>
  <!--
  <xacro:arm_joint parent="leg" child="arm" axis="1 0 0" dist="${leg_length}"/>
  -->
  <joint name="leg_arm_joint" type="revolute">
    <origin rpy="0 0 0" xyz="0 0 0.4"/>
    <parent link="leg"/>
    <child link="arm"/>
    <axis xyz="-1 0 0"/>
    <limit effort="40.0" lower="-3.14159265359" upper="3.14159265359" velocity="1.0"/>
  </joint>
  <!-- Required for ROS control -->
  <transmission name="$leg_arm_transmission">
    <type>transmission_interface/SimpleTransmission</type>
    <joint name="leg_arm_joint">
      <hardwareInterface>hardware_interface/EffortJointInterface</hardwareInterface>
    </joint>
    <actuator name="leg_arm_actuator"/>
  </transmission>
  <link name="leg">
    <visual>
      <origin rpy="0 0 0" xyz="0 0 0.2"/>
      <geometry>
        <box size="0.02 0.02 0.4"/>
      </geometry>
      <material name="orange"/>
    </visual>
    <collision>
      <origin rpy="0 0 0" xyz="0 0 0.2"/>
      <geometry>
        <box size="0.02 0.02 0.4"/>
      </geometry>
    </collision>
    <inertial>
      <origin rpy="0 0 0" xyz="0 0 0.2"/>
      <mass value="1"/>
      <inertia ixx="0.013366666666666669" ixy="0" ixz="0" iyy="0.013366666666666669" iyz="0" izz="6.666666666666667e-05"/>
    </inertial>
    <visual>
      <origin rpy="0 1.570796326795 0" xyz="0 0 0.4"/>
      <geometry>
        <cylinder length="0.025" radius="0.018"/>
      </geometry>
      <material name="gray"/>
    </visual>
    <collision>
      <origin rpy="0 1.570796326795 0" xyz="0 0 0.4"/>
      <geometry>
        <cylinder length="0.025" radius="0.018"/>
      </geometry>
    </collision>
  </link>
  <joint name="arm_finger_joint" type="revolute">
    <origin rpy="0 0 0" xyz="0 0 0.4"/>
    <parent link="arm"/>
    <child link="finger"/>
    <axis xyz="0 0 1"/>
    <limit effort="40.0" lower="-3.14159265359" upper="3.14159265359" velocity="1.0"/>
  </joint>
  <!-- Required for ROS control -->
  <transmission name="arm_finger_transmission">
    <type>transmission_interface/SimpleTransmission</type>
    <joint name="arm_finger_joint">
      <hardwareInterface>hardware_interface/EffortJointInterface</hardwareInterface>
    </joint>
    <actuator name="arm_finger_actuator"/>
  </transmission>
  <link name="arm">
    <visual>
      <origin rpy="0 0 0" xyz="0 0 0.2"/>
      <geometry>
        <box size="0.02 0.02 0.4"/>
      </geometry>
      <material name="orange"/>
    </visual>
    <collision>
      <origin rpy="0 0 0" xyz="0 0 0.2"/>
      <geometry>
        <box size="0.02 0.02 0.4"/>
      </geometry>
    </collision>
    <inertial>
      <origin rpy="0 0 0" xyz="0 0 0.2"/>
      <mass value="1"/>
      <inertia ixx="0.013366666666666669" ixy="0" ixz="0" iyy="0.013366666666666669" iyz="0" izz="6.666666666666667e-05"/>
    </inertial>
    <visual>
      <origin rpy="0 0 0" xyz="0 0 0.4"/>
      <geometry>
        <cylinder length="0.025" radius="0.018"/>
      </geometry>
      <material name="gray"/>
    </visual>
    <collision>
      <origin rpy="0 0 0" xyz="0 0 0.4"/>
      <geometry>
        <cylinder length="0.025" radius="0.018"/>
      </geometry>
    </collision>
  </link>
  <gazebo reference="arm">
    <material>Gazebo/Orange</material>
  </gazebo>
  <!-- <xacro:arm_joint parent="arm" child="finger" axis="1 0 0" dist="${hand_length}"/> -->
  <!-- End effector -->
  <link name="finger">
    <visual>
      <origin rpy="0 0 0" xyz="0 0 0.0"/>
      <geometry>
        <box size="0.02 0.02 0.0"/>
      </geometry>
      <material name="orange"/>
    </visual>
    <collision>
      <origin rpy="0 0 0" xyz="0 0 0.0"/>
      <geometry>
        <box size="0.02 0.02 0.0"/>
      </geometry>
    </collision>
    <inertial>
      <origin rpy="0 0 0" xyz="0 0 0.0"/>
      <mass value="1"/>
      <inertia ixx="3.3333333333333335e-05" ixy="0" ixz="0" iyy="3.3333333333333335e-05" iyz="0" izz="6.666666666666667e-05"/>
    </inertial>
  </link>
  <gazebo reference="finger">
    <material>Gazebo/Red</material>
  </gazebo>
</robot>
